"""Код программы"""

class MyResource:
    def __init__(self, name):
        self.name = name

    def __enter__(self):
        print(f"Acquiring {self.name}")
        return self

    def __exit__(self, exc_type, exc_value, traceback):
        print(f"Releasing {self.name}")


def use_resources():
    with MyResource("Resource A") as res_a, MyResource("Resource B") as res_b:
        raise Exception("An error occurred")


try:
    use_resources()
except Exception as e:
    print(e)



"""
В данном код наблюдается ряд ошибок:
1. Неверный вызов контекстного менеджера. В функции use_resources() делается попытка использовать два контекстных менеджера MyResource
одновременно, используя запятую в операторе with. Однако правильный вызов должен использовать блок with для каждого контекстного менеджера
отдельно. В этом случае ресурсы,захваченные res_a и res_b,не будут корректно освобождены при выходе из блока with.

Пример:
def use_resource():
    with MyResource("Resource A") as res_a:
        print(f"Используем ресурс A: {res_a.name}")
    with MyResource("Resource B") as res_b:
        print(f"Используем ресурс B: {res_b.name}")

    raise Exception("An error occurred")
"""

"""
2. Связано с переменнымм res_a и res_b, им присваиватся значения в блоке with, но затем они никак не используются. 
"""

"""
3. Связано с исключением в блоке with, так как внутри блока with генерируется исключение Exception,
но нет блока except для его обработки. Это приведет к аварийному завершению программы.
"""

"""
4. Связано с классом MyResource, так как внутри класса не реализована логика для управления захваченными ресурсами.
Он просто выводит сообщения при захвате и освобождении ресурса.
"""

"""
5. Это больше относится к читабельности кода, в блоке try except, хотелось бы видеть расписанное исключение Exception, 
чтобы понимать какое исключение сгенерируется в случае ошибки.  
"""